<?xml version="1.0"?>
<robot name="sam_bot" xmlns:xacro="http://ros.org/wiki/xacro">
	<sdf version='1.7'>
	  <model name='KK'>
	    <!--Castor-->
	    <link name='Castor wheel'>
	      <inertial>
		<mass>0.615229</mass>
		<pose>0 0 0 0 -0 0</pose>
		<inertia>
		  <ixx>1</ixx>
		  <ixy>0</ixy>
		  <ixz>0</ixz>
		  <iyy>1</iyy>
		  <iyz>0</iyz>
		  <izz>1</izz>
		</inertia>
	      </inertial>
	      <pose>-0.15 -0 0.050127 -1e-05 0 0</pose>
	      <gravity>1</gravity>
	      <self_collide>0</self_collide>
	      <kinematic>0</kinematic>
	      <enable_wind>0</enable_wind>
	      <visual name='visual'>
		<pose>0 0 0 0 -0 0</pose>
		<geometry>
		  <sphere>
		    <radius>0.05</radius>
		  </sphere>
		</geometry>
		<material>
		  <lighting>1</lighting>
		  <script>
		    <uri>file://media/materials/scripts/gazebo.material</uri>
		    <name>Gazebo/Grey</name>
		  </script>
		  <shader type='pixel'>
		    <normal_map>__default__</normal_map>
		  </shader>
		  <ambient>0.102 0.373 0.706 1</ambient>
		  <diffuse>0.7 0.7 0.7 1</diffuse>
		  <specular>0.01 0.01 0.01 1</specular>
		  <emissive>0 0 0 1</emissive>
		</material>
		<transparency>0</transparency>
		<cast_shadows>1</cast_shadows>
	      </visual>
	      <collision name='collision'>
		<laser_retro>0</laser_retro>
		<max_contacts>10</max_contacts>
		<pose>0 0 0 0 -0 0</pose>
		<geometry>
		  <sphere>
		    <radius>0.05</radius>
		  </sphere>
		</geometry>
		<surface>
		  <friction>
		    <ode>
		      <mu>1</mu>
		      <mu2>1</mu2>
		      <fdir1>0 0 0</fdir1>
		      <slip1>0</slip1>
		      <slip2>0</slip2>
		    </ode>
		    <torsional>
		      <coefficient>1</coefficient>
		      <patch_radius>0</patch_radius>
		      <surface_radius>0</surface_radius>
		      <use_patch_radius>1</use_patch_radius>
		      <ode>
		        <slip>0</slip>
		      </ode>
		    </torsional>
		  </friction>
		  <bounce>
		    <restitution_coefficient>0</restitution_coefficient>
		    <threshold>1e+06</threshold>
		  </bounce>
		  <contact>
		    <collide_without_contact>0</collide_without_contact>
		    <collide_without_contact_bitmask>1</collide_without_contact_bitmask>
		    <collide_bitmask>1</collide_bitmask>
		    <ode>
		      <soft_cfm>0</soft_cfm>
		      <soft_erp>0.2</soft_erp>
		      <kp>1e+13</kp>
		      <kd>1</kd>
		      <max_vel>0.01</max_vel>
		      <min_depth>0</min_depth>
		    </ode>
		    <bullet>
		      <split_impulse>1</split_impulse>
		      <split_impulse_penetration_threshold>-0.01</split_impulse_penetration_threshold>
		      <soft_cfm>0</soft_cfm>
		      <soft_erp>0.2</soft_erp>
		      <kp>1e+13</kp>
		      <kd>1</kd>
		    </bullet>
		  </contact>
		</surface>
	      </collision>
	    </link>
	    <joint name='castor ball joint' type='ball'>
	      <parent>chasis</parent>
	      <child>Castor wheel</child>
	      <pose>0 0 0 0 -0 0</pose>
	      <physics>
		<ode>
		  <limit>
		    <cfm>0</cfm>
		    <erp>0.4</erp>
		  </limit>
		  <suspension>
		    <cfm>0</cfm>
		    <erp>0.4</erp>
		  </suspension>
		</ode>
	      </physics>
	    </joint>
	    
	   <xacro:macro name="wheel">
	    <!--left wheel-->
	    <link name='Left wheel'>
	      <inertial>
		<mass>1.06311</mass>
		<pose>0 0 0 0 -0 0</pose>
		<inertia>
		  <ixx>1</ixx>
		  <ixy>0</ixy>
		  <ixz>0</ixz>
		  <iyy>1</iyy>
		  <iyz>0</iyz>
		  <izz>1</izz>
		</inertia>
	      </inertial>
	      <pose>0.09 -0.15 0.12 1.5707 -0 0</pose>
	      <gravity>1</gravity>
	      <self_collide>0</self_collide>
	      <kinematic>0</kinematic>
	      <enable_wind>0</enable_wind>
	      <visual name='visual'>
		<pose>0 0 0 0 -0 0</pose>
		<geometry>
		  <cylinder>
		    <radius>0.12</radius>
		    <length>0.02</length>
		  </cylinder>
		</geometry>
		<material>
		  <lighting>1</lighting>
		  <script>
		    <uri>file://media/materials/scripts/gazebo.material</uri>
		    <name>Gazebo/Grey</name>
		  </script>
		  <shader type='pixel'>
		    <normal_map>__default__</normal_map>
		  </shader>
		  <ambient>0.878 0.106 0.141 1</ambient>
		  <diffuse>0.7 0.7 0.7 1</diffuse>
		  <specular>0.01 0.01 0.01 1</specular>
		  <emissive>0 0 0 1</emissive>
		</material>
		<transparency>0</transparency>
		<cast_shadows>1</cast_shadows>
	      </visual>
	      <collision name='collision'>
		<laser_retro>0</laser_retro>
		<max_contacts>10</max_contacts>
		<pose>0 0 0 0 -0 0</pose>
		<geometry>
		  <cylinder>
		    <radius>0.12</radius>
		    <length>0.02</length>
		  </cylinder>
		</geometry>
		<surface>
		  <friction>
		    <ode>
		      <mu>1</mu>
		      <mu2>1</mu2>
		      <fdir1>0 0 0</fdir1>
		      <slip1>0</slip1>
		      <slip2>0</slip2>
		    </ode>
		    <torsional>
		      <coefficient>1</coefficient>
		      <patch_radius>0</patch_radius>
		      <surface_radius>0</surface_radius>
		      <use_patch_radius>1</use_patch_radius>
		      <ode>
		        <slip>0</slip>
		      </ode>
		    </torsional>
		  </friction>
		  <bounce>
		    <restitution_coefficient>0</restitution_coefficient>
		    <threshold>1e+06</threshold>
		  </bounce>
		  <contact>
		    <collide_without_contact>0</collide_without_contact>
		    <collide_without_contact_bitmask>1</collide_without_contact_bitmask>
		    <collide_bitmask>1</collide_bitmask>
		    <ode>
		      <soft_cfm>0</soft_cfm>
		      <soft_erp>0.2</soft_erp>
		      <kp>1e+13</kp>
		      <kd>1</kd>
		      <max_vel>0.01</max_vel>
		      <min_depth>0</min_depth>
		    </ode>
		    <bullet>
		      <split_impulse>1</split_impulse>
		      <split_impulse_penetration_threshold>-0.01</split_impulse_penetration_threshold>
		      <soft_cfm>0</soft_cfm>
		      <soft_erp>0.2</soft_erp>
		      <kp>1e+13</kp>
		      <kd>1</kd>
		    </bullet>
		  </contact>
		</surface>
	      </collision>
	    </link>
	    <joint name='left wheel joint' type='revolute'>
	      <parent>chasis</parent>
	      <child>Left wheel</child>
	      <pose>0 0 0 0 -0 0</pose>
	      <axis>
		<xyz>0 0 1</xyz>
		<limit>
		  <lower>-1.79769e+308</lower>
		  <upper>1.79769e+308</upper>
		  <effort>-1</effort>
		  <velocity>-1</velocity>
		</limit>
		<dynamics>
		  <spring_reference>0</spring_reference>
		  <spring_stiffness>0</spring_stiffness>
		  <damping>0</damping>
		  <friction>0</friction>
		</dynamics>
	      </axis>
	      <physics>
		<ode>
		  <limit>
		    <cfm>0</cfm>
		    <erp>0.4</erp>
		  </limit>
		  <suspension>
		    <cfm>0</cfm>
		    <erp>0.4</erp>
		  </suspension>
		</ode>
	      </physics>
	    </joint>
	    
	    <!--right wheel-->
	    <link name='Right wheel'>
	      <inertial>
		<mass>1.06311</mass>
		<pose>0 0 0 0 -0 0</pose>
		<inertia>
		  <ixx>1</ixx>
		  <ixy>0</ixy>
		  <ixz>0</ixz>
		  <iyy>1</iyy>
		  <iyz>0</iyz>
		  <izz>1</izz>
		</inertia>
	      </inertial>
	      <pose>0.09 0.15 0.12 1.5707 -0 0</pose>
	      <gravity>1</gravity>
	      <self_collide>0</self_collide>
	      <kinematic>0</kinematic>
	      <enable_wind>0</enable_wind>
	      <visual name='visual'>
		<pose>0 0 0 0 -0 0</pose>
		<geometry>
		  <cylinder>
		    <radius>0.12</radius>
		    <length>0.02</length>
		  </cylinder>
		</geometry>
		<material>
		  <lighting>1</lighting>
		  <script>
		    <uri>file://media/materials/scripts/gazebo.material</uri>
		    <name>Gazebo/Grey</name>
		  </script>
		  <shader type='pixel'>
		    <normal_map>__default__</normal_map>
		  </shader>
		  <ambient>0.878 0.106 0.141 1</ambient>
		  <diffuse>0.7 0.7 0.7 1</diffuse>
		  <specular>0.01 0.01 0.01 1</specular>
		  <emissive>0 0 0 1</emissive>
		</material>
		<transparency>0</transparency>
		<cast_shadows>1</cast_shadows>
	      </visual>
	      <collision name='collision'>
		<laser_retro>0</laser_retro>
		<max_contacts>10</max_contacts>
		<pose>0 0 0 0 -0 0</pose>
		<geometry>
		  <cylinder>
		    <radius>0.12</radius>
		    <length>0.02</length>
		  </cylinder>
		</geometry>
		<surface>
		  <friction>
		    <ode>
		      <mu>1</mu>
		      <mu2>1</mu2>
		      <fdir1>0 0 0</fdir1>
		      <slip1>0</slip1>
		      <slip2>0</slip2>
		    </ode>
		    <torsional>
		      <coefficient>1</coefficient>
		      <patch_radius>0</patch_radius>
		      <surface_radius>0</surface_radius>
		      <use_patch_radius>1</use_patch_radius>
		      <ode>
		        <slip>0</slip>
		      </ode>
		    </torsional>
		  </friction>
		  <bounce>
		    <restitution_coefficient>0</restitution_coefficient>
		    <threshold>1e+06</threshold>
		  </bounce>
		  <contact>
		    <collide_without_contact>0</collide_without_contact>
		    <collide_without_contact_bitmask>1</collide_without_contact_bitmask>
		    <collide_bitmask>1</collide_bitmask>
		    <ode>
		      <soft_cfm>0</soft_cfm>
		      <soft_erp>0.2</soft_erp>
		      <kp>1e+13</kp>
		      <kd>1</kd>
		      <max_vel>0.01</max_vel>
		      <min_depth>0</min_depth>
		    </ode>
		    <bullet>
		      <split_impulse>1</split_impulse>
		      <split_impulse_penetration_threshold>-0.01</split_impulse_penetration_threshold>
		      <soft_cfm>0</soft_cfm>
		      <soft_erp>0.2</soft_erp>
		      <kp>1e+13</kp>
		      <kd>1</kd>
		    </bullet>
		  </contact>
		</surface>
	      </collision>
	    </link>
	    <joint name='right wheel joint' type='revolute'>
	      <parent>chasis</parent>
	      <child>Right wheel</child>
	      <pose>0 0 0 0 -0 0</pose>
	      <axis>
		<xyz>0 0 -1</xyz>
		<limit>
		  <lower>-1.79769e+308</lower>
		  <upper>1.79769e+308</upper>
		  <effort>-1</effort>
		  <velocity>-1</velocity>
		</limit>
		<dynamics>
		  <spring_reference>0</spring_reference>
		  <spring_stiffness>0</spring_stiffness>
		  <damping>0</damping>
		  <friction>0</friction>
		</dynamics>
	      </axis>
	      <physics>
		<ode>
		  <limit>
		    <cfm>0</cfm>
		    <erp>0.4</erp>
		  </limit>
		  <suspension>
		    <cfm>0</cfm>
		    <erp>0.4</erp>
		  </suspension>
		</ode>
	      </physics>
	    </joint>
	   </xacro:macro>
	    
	    <!--chasis-->
	    <link name='chasis'>
	      <inertial>
		<mass>19.74</mass>
		<inertia>
		  <ixx>600</ixx>
		  <ixy>-1.3e-20</ixy>
		  <ixz>1.3e-20</ixz>
		  <iyy>600</iyy>
		  <iyz>1.3e-20</iyz>
		  <izz>600</izz>
		</inertia>
		<pose>0 0 0.146701 0 -0 0</pose>
	      </inertial>
	      <self_collide>0</self_collide>
	      <enable_wind>0</enable_wind>
	      <kinematic>0</kinematic>
	      <pose>0 0 0.146701 0 -0 0</pose>
	      <gravity>1</gravity>
	      <visual name='visual'>
		<geometry>
		  <box>
		    <size>0.4 0.28 0.15</size>
		  </box>
		</geometry>
		<material>
		  <script>
		    <name>Gazebo/Grey</name>
		    <uri>file://media/materials/scripts/gazebo.material</uri>
		  </script>
		  <shader type='pixel'>
		    <normal_map>__default__</normal_map>
		  </shader>
		  <ambient>0.506 0.239 0.612 1</ambient>
		  <diffuse>0.7 0.7 0.7 1</diffuse>
		  <specular>0.01 0.01 0.01 1</specular>
		  <emissive>0 0 0 1</emissive>
		</material>
		<pose>0 0 0 0 -0 0</pose>
		<transparency>0</transparency>
		<cast_shadows>1</cast_shadows>
	      </visual>
	      <collision name='collision'>
		<laser_retro>0</laser_retro>
		<max_contacts>10</max_contacts>
		<pose>0 0 0 0 -0 0</pose>
		<geometry>
		  <box>
		    <size>0.4 0.28 0.15</size>
		  </box>
		</geometry>
		<surface>
		  <friction>
		    <ode>
		      <mu>1</mu>
		      <mu2>1</mu2>
		      <fdir1>0 0 0</fdir1>
		      <slip1>0</slip1>
		      <slip2>0</slip2>
		    </ode>
		    <torsional>
		      <coefficient>1</coefficient>
		      <patch_radius>0</patch_radius>
		      <surface_radius>0</surface_radius>
		      <use_patch_radius>1</use_patch_radius>
		      <ode>
		        <slip>0</slip>
		      </ode>
		    </torsional>
		  </friction>
		  <bounce>
		    <restitution_coefficient>0</restitution_coefficient>
		    <threshold>1e+06</threshold>
		  </bounce>
		  <contact>
		    <collide_without_contact>0</collide_without_contact>
		    <collide_without_contact_bitmask>1</collide_without_contact_bitmask>
		    <collide_bitmask>1</collide_bitmask>
		    <ode>
		      <soft_cfm>0</soft_cfm>
		      <soft_erp>0.2</soft_erp>
		      <kp>1e+13</kp>
		      <kd>1</kd>
		      <max_vel>0.01</max_vel>
		      <min_depth>0</min_depth>
		    </ode>
		    <bullet>
		      <split_impulse>1</split_impulse>
		      <split_impulse_penetration_threshold>-0.01</split_impulse_penetration_threshold>
		      <soft_cfm>0</soft_cfm>
		      <soft_erp>0.2</soft_erp>
		      <kp>1e+13</kp>
		      <kd>1</kd>
		    </bullet>
		  </contact>
		</surface>
	      </collision>
	    </link>
	    
	    <!--chasis-->
	    <model name='camera'>
	      <pose>-0.001114 -0.002694 0.270734 0 -0 0</pose>
	      <link name='link'>
		<inertial>
		  <mass>0.1</mass>
		  <pose>0 0 0 0 -0 0</pose>
		  <inertia>
		    <ixx>1</ixx>
		    <ixy>0</ixy>
		    <ixz>0</ixz>
		    <iyy>1</iyy>
		    <iyz>0</iyz>
		    <izz>1</izz>
		  </inertia>
		</inertial>
		<collision name='collision'>
		  <geometry>
		    <box>
		      <size>0.1 0.1 0.1</size>
		    </box>
		  </geometry>
		  <max_contacts>10</max_contacts>
		  <surface>
		    <contact>
		      <ode/>
		    </contact>
		    <bounce/>
		    <friction>
		      <torsional>
		        <ode/>
		      </torsional>
		      <ode/>
		    </friction>
		  </surface>
		</collision>
		<visual name='visual'>
		  <geometry>
		    <box>
		      <size>0.1 0.1 0.1</size>
		    </box>
		  </geometry>
		</visual>
		<sensor name='camera' type='camera'>
		  <camera>
		    <horizontal_fov>1.047</horizontal_fov>
		    <image>
		      <width>320</width>
		      <height>240</height>
		    </image>
		    <clip>
		      <near>0.1</near>
		      <far>100</far>
		    </clip>
		  </camera>
		  <always_on>1</always_on>
		  <update_rate>30</update_rate>
		  <visualize>1</visualize>
		</sensor>
		<self_collide>0</self_collide>
		<enable_wind>0</enable_wind>
		<kinematic>0</kinematic>
	      </link>
	    </model>
	    <joint name='chasis_JOINT_1' type='fixed'>
	      <parent>chasis</parent>
	      <child>camera::link</child>
	      <pose>0 0 0 0 -0 0</pose>
	      <physics>
		<ode>
		  <limit>
		    <cfm>0</cfm>
		    <erp>0.2</erp>
		  </limit>
		  <suspension>
		    <cfm>0</cfm>
		    <erp>0.2</erp>
		  </suspension>
		</ode>
	      </physics>
	    </joint>
	    
	    
	    <static>0</static>
	    <allow_auto_disable>1</allow_auto_disable>
	    <plugin name='camera_controller' filename='libgazebo_ros_camera.so'/>
	    <plugin name='differential_drive_controller' filename='ibdiffdrive_plugin.so'/>
	  </model>
	</sdf>
</robot>
